Workbook

Sheet Balance Sheet
A4: CONSOLIDATED BALANCE SHEETS - USD ($) | B4: Feb. 01, 2025 | C4: Feb. 03, 2024
A5: $ in Millions
A6: Current assets:
A7: Cash and cash equivalents | B7: 948.3 | C7: 950.8
A8: Accounts receivable, net | B8: 1028.4 | C8: 1121.6
A9: Inventories | B9: 1029.7 | C9: 864.4
A10: Prepaid expenses and other current assets | B10: 113.9 | C10: 125.9
A11: Total current assets | B11: 3120.3 | C11: 3062.7
A12: Property and equipment, net | B12: 790.5 | C12: 756
A13: Goodwill | B13: 11586.9 | C13: 11586.9
A14: Acquired intangible assets, net | B14: 2710.6 | C14: 4004.1
A15: Deferred tax assets | B15: 401.2 | C15: 311.9
A16: Other non-current assets | B16: 1595 | C16: 1506.9
A17: Total assets | B17: 20204.5 | C17: 21228.5
A18: Current liabilities:
A19: Accounts payable | B19: 622.2 | C19: 411.3
A20: Accrued liabilities | B20: 972.6 | C20: 1032.9
A21: Accrued employee compensation | B21: 302.5 | C21: 262.7
A22: Short-term debt | B22: 129.5 | C22: 107.3
A23: Total current liabilities | B23: 2026.8 | C23: 1814.2
A24: Long-term debt | B24: 3934.3 | C24: 4058.6
A25: Other non-current liabilities | B25: 816.4 | C25: 524.3
A26: Total liabilities | B26: 6777.5 | C26: 6397.1
A27: Commitments and contingencies (Note 8)
A28: Stockholders’ equity:
A29: Preferred stock, $0.002 par value; 8.0 shares authorized; no shares issued and outstanding | B29: 0 | C29: 0
A30: Common stock, $0.002 par value; 1.3 billion shares authorized; 866.0 and 865.5 shares issued and outstanding in fiscal 2025 and 2024, respectively | B30: 1.7 | C30: 1.7
A31: Additional paid-in capital | B31: 14534.1 | C31: 14845.3
A32: Accumulated other comprehensive income | B32: 0.4 | C32: 1.1
A33: Accumulated deficit | B33: -1109.2 | C33: -16.7
A34: Total stockholders’ equity | B34: 13427 | C34: 14831.4
A35: Total liabilities and stockholders’ equity | B35: 20204.5 | C35: 21228.5

Sheet Income Statement
A3: CONSOLIDATED STATEMENTS OF OPERATIONS - USD ($) | B3: 12 Months Ended
A4: shares in Millions, $ in Millions
B5: Feb. 01, 2025 | C5: Feb. 03, 2024 | D5: Jan. 28, 2023
A6: Income Statement [Abstract]
A7: Net revenue | B7: 5767.3 | C7: 5507.7 | D7: 5919.6
A8: Cost of goods sold | B8: 3385.1 | C8: 3214.1 | D8: 2932.1
A9: Gross profit | B9: 2382.2 | C9: 2293.6 | D9: 2987.5
A10: Operating expenses:
A11: Research and development | B11: 1950.4 | C11: 1896.2 | D11: 1784.3
A12: Selling, general and administrative | B12: 798.2 | C12: 834 | D12: 843.6
A13: Legal settlement | B13: 0 | C13: 0 | D13: 100
A14: Restructuring related charges | B14: 353.9 | C14: 131.1 | D14: 21.6
A15: Total operating expenses | B15: 3102.5 | C15: 2861.3 | D15: 2749.5
A16: Operating income (loss) | B16: -720.3 | C16: -567.7 | D16: 238
A17: Interest expense | B17: -189.4 | C17: -211.7 | D17: -170.6
A18: Interest income and other, net | B18: 15 | C18: 20.7 | D18: 17.7
A19: Interest and other loss, net | B19: -174.4 | C19: -191 | D19: -152.9
A20: Income (loss) before income taxes | B20: -894.7 | C20: -758.7 | D20: 85.1
A21: Provision (benefit) for income taxes | B21: -9.7 | C21: 174.7 | D21: 248.6
A22: Net loss | B22: -885 | C22: -933.4 | D22: -163.5
... A24: Net loss per share — diluted (in dollars per share) | B24: -1.02 | C24: -1.08 | D24: -0.19
A25: Weighted-average shares:
A26: Basic (in shares) | B26: 865.5 | C26: 861.3 | D26: 851.4
A27: Diluted (in shares) | B27: 865.5 | C27: 861.3 | D27: 851.4

Sheet Cash Flow
A3: CONSOLIDATED STATEMENTS OF CASH FLOWS - USD ($) | B3: 12 Months Ended
A4: $ in Millions
A5: Feb. 01, 2025 | B5: Feb. 03, 2024 | C5: Jan. 28, 2023
A6: Cash flows from operating activities:
A7: Net loss | B7: -885 | C7: -933.4 | D7: -163.5
A8: Adjustments to reconcile net loss to net cash provided by operating activities:
A9: Depreciation and amortization | B9: 304.3 | C9: 299.8 | D9: 304.9
A10: Stock-based compensation | B10: 597.4 | C10: 609.8 | D10: 552.4
A11: Amortization of acquired intangible assets | B11: 1052.6 | C11: 1097.9 | D11: 1087.4
A12: Amortization of inventory fair value adjustment associated with acquisitions | B12: 0 | C12: 0 | D12: 38.7
A13: Restructuring related impairment charges | B13: 528.8 | C13: 32.9 | D13: 5.6
A14: Deferred income taxes | B14: -111.9 | C14: 150.8 | D14: 50.4
A15: Other expense, net | B15: 65.9 | C15: 54.9 | D15: 62.7
A16: Changes in assets and liabilities, net of acquisitions:
A17: Accounts receivable | B17: 93.2 | C17: 70.6 | D17: -142.7
A18: Prepaid expenses and other assets | B18: 3.4 | C18: -93.1 | D18: -480.4
A19: Inventories | B19: -230 | C19: 201.9 | D19: -385.9
A20: Accounts payable | B20: 181.5 | C20: -149.1 | D20: -87.8
A21: Accrued employee compensation | B21: 43.5 | C21: 18.3 | D21: 2.5
A22: Accrued liabilities and other non-current liabilities | B22: 37.5 | C22: 9.2 | D22: 444.5
A23: Net cash provided by operating activities | B23: 1681.2 | C23: 1370.5 | D23: 1288.8
A24: Cash flows from investing activities:
A25: Purchases of technology licenses | B25: -7 | C25: -13.9 | D25: -11.1
A26: Purchases of property and equipment | B26: -284.6 | C26: -336.3 | D26: -206.2
A27: Acquisitions, net of cash acquired | B27: -10.4 | C27: 0 | D27: -112.3
A28: Other, net | B28: 1.3 | C28: -0.3 | D28: 1.2
A29: Net cash used in investing activities | B29: -300.7 | C29: -350.5 | D29: -328.4
A30: Cash flows from financing activities:
A31: Repurchases of common stock | B31: -725 | C31: -150 | D31: -115
A32: Proceeds from employee stock plans | B32: 87.6 | C32: 99.2 | D32: 91.3
A33: Tax withholding paid on behalf of employees for net share settlement | B33: -274.9 | C33: -223.7 | D33: -227.6
A34: Dividend payments to stockholders | B34: -207.5 | C34: -206.8 | D34: -204.4
A35: Payments on technology license obligations | B35: -153.6 | C35: -150.3 | D35: -142.5
A36: Proceeds from borrowings | B36: 0 | C36: 1295.3 | D36: 200
A37: Principal payments of debt | B37: -109.4 | C37: -1622.5 | D37: -265.6
A38: Other, net | B38: -0.2 | C38: -21.4 | D38: 0.9
A39: Net cash used in financing activities | B39: -1383 | C39: -980.2 | D39: -662.9
A40: Net increase (decrease) in cash and cash equivalents | B40: -2.5 | C40: 39.8 | D40: 297.5
A41: Cash and cash equivalents at beginning of the year | B41: 950.8 | C41: 911 | D41: 613.5
A42: Cash and cash equivalents at end of the year | B42: 948.3 | C42: 950.8 | D42: 911

Sheet DCF
B6: DCF | E6: Historical | H6: Forecast
E7: 2023 | F7: =E7+1 -> 2024 | G7: =F7+1 -> 2025 | H7: =G7+1 -> 2026 | I7: =H7+1 -> 2027 | J7: =I7+1 -> 2028 | K7: =J7+1 -> 2029 | L7: =K7+1 -> 2030 | M7: T
B8: Income Statement
B9: Revenues | E9: ='Income Statement'!D7 -> 5919.6 | F9: ='Income Statement'!C7 -> 5507.7 | G9: ='Income Statement'!B7 -> 5767.3 | H9: =G9*(1+H10) -> 6632.395 | I9: =H9*(1+I10) -> 7958.874 | J9: =I9*(1+J10) -> 10346.536 | K9: =J9*(1+K10) -> 14485.151 | L9: =K9*(1+L10) -> 18106.438
B10: % growth | E10: 0.3 | F10: =F9/E9 -1 -> -0.069582404 | G10: =G9/F9 -1 -> 0.047134012 | H10: 0.15 | I10: 0.2 | J10: 0.3 | K10: 0.4 | L10: 0.25
B11: Cost of Goods Sold | E11: ='Income Statement'!D8 -> 2932.1 | F11: ='Income Statement'!C8 -> 3214.1 | G11: ='Income Statement'!B8 -> 3385.1 | H11: =H12*H9 -> 3682.8198 | I11: =I12*I9 -> 4578.4469 | J11: =J12*J9 -> 5923.3498 | K11: =K12*K9 -> 8222.9139 | L11: =L12*L9 -> 10353.49
B12: % of Revenue | E12: =E11/E$9 -> 0.49532063 | F12: =F11/F$9 -> 0.58356483 | G12: =G11/G$9 -> 0.5869471 | H12: =AVERAGE(E12:G12) -> 0.55527752 | I12: =AVERAGE(F12:H12) -> 0.57526315 | J12: =AVERAGE(G12:I12) -> 0.57249592 | K12: =AVERAGE(H12:J12) -> 0.56767886 | L12: =AVERAGE(I12:K12) -> 0.57181264
B14: Gross Profit | E14: =E9-E11 -> 2987.5 | F14: =F9-F11 -> 2293.6 | G14: =G9-G11 -> 2382.2 | H14: =H9-H11 -> 2949.5752 | I14: =I9-I11 -> 3380.4271 | J14: =J9-J11 -> 4423.1864 | K14: =K9-K11 -> 6262.2368 | L14: =L9-L11 -> 7752.948
B15: % of Revenue | E15: =E14/E$9 -> 0.50467937 | F15: =F14/F$9 -> 0.41643517 | G15: =G14/G$9 -> 0.4130529 | H15: =H14/H$9 -> 0.44472248 | I15: =I14/I$9 -> 0.42473685 | J15: =J14/J$9 -> 0.42750408 | K15: =K14/K$9 -> 0.43232114 | L15: =L14/L$9 -> 0.42818736
B17: Research and Development | E17: ='Income Statement'!D11 -> 1784.3 | F17: ='Income Statement'!C11 -> 1896.2 | G17: ='Income Statement'!B11 -> 1950.4 | H17: =H18*H$9 -> 1989.7185 | I17: =I18*I$9 -> 1989.7185 | J17: =J18*J$9 -> 2586.634 | K17: =K18*K$9 -> 3621.2877 | L17: =L18*L$9 -> 4526.6096
B18: % of Revenue | E18: =E17/E$9 -> 0.30142239 | F18: =F17/F$9 -> 0.34428164 | G18: =G17/G$9 -> 0.33818251 | H18: 0.3 | I18: 0.25 | J18: 0.25 | K18: 0.25 | L18: 0.25
B19: SG&A | E19: ='Income Statement'!D12 -> 843.6 | F19: ='Income Statement'!C12 -> 834 | G19: ='Income Statement'!B12 -> 798.2 | H19: =H20*H$9 -> 955.80546 | I19: =I20*I$9 -> 1034.6536 | J19: =J20*J$9 -> 1241.5843 | K19: =K20*K$9 -> 1593.3666 | L19: =L20*L$9 -> 2353.837
B20: % of Revenue | E20: =E19/E$9 -> 0.14250963 | F20: =F19/F$9 -> 0.15142437 | G20: =G19/G$9 -> 0.13840098 | H20: =AVERAGE(E20:G20) -> 0.14411166 | I20: 0.13 | J20: 0.12 | K20: 0.11 | L20: 0.13
B21: Legal | E21: ='Income Statement'!D13 -> 100 | F21: ='Income Statement'!C13 -> 0 | G21: ='Income Statement'!B13 -> 0 | H21: =H22*H$9 -> 0 | I21: =I22*I$9 -> 0 | J21: =J22*J$9 -> 0 | K21: =K22*K$9 -> 0 | L21: =L22*L$9 -> 0
B22: % of Revenue | E22: =E21/E$9 -> 0.016893033 | F22: =F21/F$9 -> 0 | G22: =G21/G$9 -> 0 | H22: 0 | I22: 0 | J22: 0 | K22: 0 | L22: 0
B23: Restructuring | E23: ='Income Statement'!D14 -> 21.6 | F23: ='Income Statement'!C14 -> 131.1 | G23: ='Income Statement'!B14 -> 353.9 | H23: =H24*H9 -> 0 | I23: =I24*I9 -> 0 | J23: =J24*J9 -> 0 | K23: =K24*K9 -> 0 | L23: =L24*L9 -> 0
B24: % of Revenue | E24: =E23/E$9 -> 0.0036488952 | F24: =F23/F$9 -> 0.023803039 | G24: =G23/G$9 -> 0.061363203 | H24: 0 | I24: 0 | J24: 0 | K24: 0 | L24: 0
B26: Total Operating Expenses | E26: =E17+E19+E21+E23 -> 2749.5 | F26: =F17+F19+F21+F23 -> 2861.3 | G26: =G17+G19+G21+G23 -> 3102.5 | H26: =H17+H19+H21+H23 -> 2945.524 | I26: =I17+I19+I21+I23 -> 3024.3721 | J26: =J17+J19+J21+J23 -> 3828.2184 | K26: =K17+K19+K21+K23 -> 5214.6542 | L26: =L17+L19+L21+L23 -> 6880.4466
B27: % of Revenue | E27: =E26/E$9 -> 0.46447395 | F27: =F26/F$9 -> 0.51950905 | G27: =G26/G$9 -> 0.5379467 | H27: =H26/H$9 -> 0.44411166 | I27: =I26/I$9 -> 0.38 | J27: =J26/J$9 -> 0.37 | K27: =K26/K$9 -> 0.36 | L27: =L26/L$9 -> 0.38
B29: Operating Income | E29: =E14-E26 -> 238 | F29: =F14-F26 -> -567.7 | G29: =G14-G26 -> -720.3 | H29: =H14-H26 -> 4.0512019 | I29: =I14-I26 -> 356.05497 | J29: =J14-J26 -> 594.96803 | K29: =K14-K26 -> 1047.5826 | L29: =L14-L26 -> 872.50139
B30: % of Revenue | E30: =E29/E$9 -> 0.040205419 | F30: =F29/F$9 -> -0.10307388 | G30: =G29/G$9 -> -0.1248938 | H30: =H29/H$9 -> 0.00061082037 | I30: =I29/I$9 -> 0.044736852 | J30: =J29/J$9 -> 0.057504078 | K30: =K29/K$9 -> 0.072321137 | L30: =L29/L$9 -> 0.048187356
B32: Interest Expense | E32: ='Income Statement'!D17*-1 -> 170.6 | F32: ='Income Statement'!C17*-1 -> 211.7 | G32: ='Income Statement'!B17*-1 -> 189.4 | H32: =H33*H$9 -> 221.29414 | I32: =I33*I$9 -> 277.61366 | J32: =J33*J$9 -> 348.6334 | K32: =K33*K$9 -> 492.21668 | L32: =L33*L$9 -> 618.98346
B33: % of Revenue | E33: =E32/E$9 -> 0.028819515 | F33: =F32/F$9 -> 0.038437097 | G33: =G32/G$9 -> 0.032840324 | H33: =AVERAGE(E33:G33) -> 0.033365645 | I33: =AVERAGE(F33:H33) -> 0.034881022 | J33: =AVERAGE(G33:I33) -> 0.033695664 | K33: =AVERAGE(H33:J33) -> 0.033980777 | L33: =AVERAGE(I33:K33) -> 0.034185821
B34: Interest Income | E34: ='Income Statement'!D18 -> 17.7 | F34: ='Income Statement'!C18 -> 20.7 | G34: ='Income Statement'!B18 -> 15 | H34: =H35*H$9 -> 20.669443 | I34: =I35*I$9 -> 25.138587 | J34: =J35*J$9 -> 30.611498 | K34: =K35*K$9 -> 44.583464 | L34: =L35*L$9 -> 55.496579
B35: % of Revenue | E35: =E34/E$9 -> 0.0029900669 | F35: =F34/F$9 -> 0.0037583746 | G35: =G34/G$9 -> 0.0026008704 | H35: =AVERAGE(E35:G35) -> 0.0031164373 | I35: =AVERAGE(F35:H35) -> 0.0031585608 | J35: =AVERAGE(G35:I35) -> 0.0029586228 | K35: =AVERAGE(H35:J35) -> 0.0030778737 | L35: =AVERAGE(I35:K35) -> 0.0030650191
B37: Pretax Income | E37: =E29-E32+E34 -> 85.1 | F37: =F29-F32+F34 -> -758.7 | G37: =G29-G32+G34 -> -894.7 | H37: =H29-H32+H34 -> -196.57349 | I37: =I29-I32+I34 -> 103.5799 | J37: =J29-J32+J34 -> 276.94612 | K37: =K29-K32+K34 -> 599.94936 | L37: =L29-L32+L34 -> 309.01451
B38: % of Revenue | E38: =E37/E$9 -> 0.014375971 | F38: =F37/F$9 -> -0.1377526 | G38: =G37/G$9 -> -0.15513325 | H38: =H37/H$9 -> -0.029638388 | I38: =I37/I$9 -> 0.013014391 | J38: =J37/J$9 -> 0.026767037 | K38: =K37/K$9 -> 0.041418234 | L38: =L37/L$9 -> 0.017066554
B40: Income Taxes | E40: ='Income Statement'!D21*-1 -> -248.6 | F40: ='Income Statement'!C21*-1 -> -174.7 | G40: ='Income Statement'!B21*-1 -> 9.7 | H40: =AVERAGE(E40:G40) -> -137.86667 | I40: =AVERAGE(F40:H40) -> -100.95556 | J40: =AVERAGE(G40:I40) -> -76.374074 | K40: =AVERAGE(H40:J40) -> -105.06543 | L40: =AVERAGE(I40:K40) -> -94.131687
B42: Net Loss | E42: =E37+E40 -> -163.5 | F42: =F37+F40 -> -933.4 | G42: =G37+G40 -> -885 | H42: =H37+H40 -> -334.44016 | I42: =I37+I40 -> 2.6243395 | J42: =J37+J40 -> 200.57205 | K42: =K37+K40 -> 494.88393 | L42: =L37+L40 -> 214.88282
B43: % of Revenue | E43: =E42/E$9 -> -0.027620109 | F43: =F42/F$9 -> -0.16947183 | G43: =G42/G$9 -> -0.15345136 | H43: =H42/H$9 -> -0.050425248 | I43: =I42/I$9 -> 0.00032973753 | J43: =J42/J$9 -> 0.019385429 | K43: =K42/K$9 -> 0.034164914 | L43: =L42/L$9 -> 0.011867758
B46: Adj. EBITDA
B47: =B42 -> Net Loss | E47: =E42 -> -163.5 | F47: =F42 -> -933.4 | G47: =G42 -> -885 | H47: =H42 -> -334.44016 | I47: =I42 -> 2.6243395 | J47: =J42 -> 200.57205 | K47: =K42 -> 494.88393 | L47: =L42 -> 214.88282
B48: Depreciation | E48: ='Cash Flow'!D9 -> 304.9 | F48: ='Cash Flow'!C9 -> 299.8 | G48: ='Cash Flow'!B9 -> 304.3 | H48: =H49*H$9 -> 331.61975 | I48: =I49*I$9 -> 397.9437 | J48: =J49*J$9 -> 517.32681 | K48: =K49*K$9 -> 724.25753 | L48: =L49*L$9 -> 905.32192
B49: % of Revenue | E49: =E48/E$9 -> 0.051506859 | F49: =F48/F$9 -> 0.054432885 | G49: =G48/G$9 -> 0.052762991 | H49: 0.05 | I49: 0.05 | J49: 0.05 | K49: 0.05 | L49: 0.05
B50: Stock Based Compensation | E50: ='Cash Flow'!D10 -> 552.4 | F50: ='Cash Flow'!C10 -> 609.8 | G50: ='Cash Flow'!B10 -> 597.4 | H50: =H51*H$9 -> 680.08321 | I50: =I51*I$9 -> 840.56675 | J50: =J51*J$9 -> 1075.1341 | K50: =K51*K$9 -> 1506.7736 | L50: =L51*L$9 -> 1892.4137
B51: % of Revenue | E51: =E50/E$9 -> 0.093317116 | F51: =F50/F$9 -> 0.11071772 | G51: =G50/G$9 -> 0.103584 | H51: =AVERAGE(E51:G51) -> 0.10253961 | I51: =AVERAGE(F51:H51) -> 0.10561378 | J51: =AVERAGE(G51:I51) -> 0.10391246 | K51: =AVERAGE(H51:J51) -> 0.10402195 | L51: =AVERAGE(I51:K51) -> 0.10451606
B52: Amortization | E52: ='Cash Flow'!D12+'Cash Flow'!D11 -> 1126.1 | F52: ='Cash Flow'!C12+'Cash Flow'!C11 -> 1097.9 | G52: ='Cash Flow'!B12+'Cash Flow'!B11 -> 1052.6 | H52: =H53*H$9 -> 1264.7608 | I52: =I53*I$9 -> 1518.9386 | J52: =J53*J$9 -> 1945.3372 | K52: =K53*K$9 -> 2750.0593 | L52: =L53*L$9 -> 3432.4998
B53: % of Revenue | E53: =E52/E$9 -> 0.19023245 | F53: =F52/F$9 -> 0.19933911 | G53: =G52/G$9 -> 0.18251175 | H53: =AVERAGE(E53:G53) -> 0.19069443 | I53: =AVERAGE(F53:H53) -> 0.19084843 | J53: =AVERAGE(G53:I53) -> 0.1880182 | K53: =AVERAGE(H53:J53) -> 0.18985369 | L53: =AVERAGE(I53:K53) -> 0.18957344
B54: Taxes | E54: =E40 -> -248.6 | F54: =F40 -> -174.7 | G54: =G40 -> 9.7 | H54: =H40 -> -137.86667 | I54: =I40 -> -100.95556 | J54: =J40 -> -76.374074 | K54: =K40 -> -105.06543 | L54: =L40 -> -94.131687
B56: Adj. EBITDA | E56: =E47+E48+E50+E52-E54 -> 2068.5 | F56: =F47+F48+F50+F52-F54 -> 1248.8 | G56: =G47+G48+G50+G52+G54 -> 1079 | H56: =H47+H48+H50+H52-H54 -> 2079.8903 | I56: =I47+I48+I50+I52-I54 -> 2861.029 | J56: =J47+J48+J50+J52-J54 -> 3814.7441 | K56: =K47+K48+K50+K52-K54 -> 5581.0398 | L56: =L47+L48+L50+L52-L54 -> 6539.2499
...
